2025-08-07 20:40:56,309 (37375/completion_refresh) litecli.sqlcompleter ERROR - Failed to get function names.
Traceback (most recent call last):
  File "/opt/homebrew/Cellar/litecli/1.15.0/libexec/lib/python3.13/site-packages/litecli/sqlcompleter.py", line 369, in extend_functions
    func_data = [self.escaped_names(d) for d in func_data]
                                                ^^^^^^^^^
  File "/opt/homebrew/Cellar/litecli/1.15.0/libexec/lib/python3.13/site-packages/litecli/sqlexecute.py", line 188, in functions
    cur.execute(self.functions_query % self.dbname)
    ~~~~~~~~~~~^^^^^^^^^^^^^^^^^^^^^^^^^^^^^^^^^^^^
sqlite3.OperationalError: no such table: INFORMATION_SCHEMA.ROUTINES
2025-08-07 20:41:00,775 (37375/MainThread) litecli.main ERROR - sql: 'show db;', error: OperationalError('near "show": syntax error')
2025-08-07 20:41:00,780 (37375/MainThread) litecli.main ERROR - traceback: 'Traceback (most recent call last):\n  File "/opt/homebrew/Cellar/litecli/1.15.0/libexec/lib/python3.13/site-packages/litecli/sqlexecute.py", line 123, in run\n    for result in special.execute(cur, sql):\n                  ~~~~~~~~~~~~~~~^^^^^^^^^^\n  File "/opt/homebrew/Cellar/litecli/1.15.0/libexec/lib/python3.13/site-packages/litecli/packages/special/main.py", line 107, in execute\n    raise CommandNotFound\nlitecli.packages.special.main.CommandNotFound\n\nDuring handling of the above exception, another exception occurred:\n\nTraceback (most recent call last):\n  File "/opt/homebrew/Cellar/litecli/1.15.0/libexec/lib/python3.13/site-packages/litecli/main.py", line 501, in one_iteration\n    mutating = output_res(res, start)\n  File "/opt/homebrew/Cellar/litecli/1.15.0/libexec/lib/python3.13/site-packages/litecli/main.py", line 392, in output_res\n    for title, cur, headers, status in res:\n                                       ^^^\n  File "/opt/homebrew/Cellar/litecli/1.15.0/libexec/lib/python3.13/site-packages/litecli/sqlexecute.py", line 130, in run\n    cur.execute(sql)\n    ~~~~~~~~~~~^^^^^\nsqlite3.OperationalError: near "show": syntax error\n'
2025-08-07 20:41:54,625 (37375/MainThread) litecli.main ERROR - sql: '.sch', error: OperationalError('near ".": syntax error')
2025-08-07 20:41:54,628 (37375/MainThread) litecli.main ERROR - traceback: 'Traceback (most recent call last):\n  File "/opt/homebrew/Cellar/litecli/1.15.0/libexec/lib/python3.13/site-packages/litecli/sqlexecute.py", line 123, in run\n    for result in special.execute(cur, sql):\n                  ~~~~~~~~~~~~~~~^^^^^^^^^^\n  File "/opt/homebrew/Cellar/litecli/1.15.0/libexec/lib/python3.13/site-packages/litecli/packages/special/main.py", line 107, in execute\n    raise CommandNotFound\nlitecli.packages.special.main.CommandNotFound\n\nDuring handling of the above exception, another exception occurred:\n\nTraceback (most recent call last):\n  File "/opt/homebrew/Cellar/litecli/1.15.0/libexec/lib/python3.13/site-packages/litecli/main.py", line 501, in one_iteration\n    mutating = output_res(res, start)\n  File "/opt/homebrew/Cellar/litecli/1.15.0/libexec/lib/python3.13/site-packages/litecli/main.py", line 392, in output_res\n    for title, cur, headers, status in res:\n                                       ^^^\n  File "/opt/homebrew/Cellar/litecli/1.15.0/libexec/lib/python3.13/site-packages/litecli/sqlexecute.py", line 130, in run\n    cur.execute(sql)\n    ~~~~~~~~~~~^^^^^\nsqlite3.OperationalError: near ".": syntax error\n'
2025-08-08 22:54:39,003 (68090/completion_refresh) litecli.sqlcompleter ERROR - Failed to get function names.
Traceback (most recent call last):
  File "/opt/homebrew/Cellar/litecli/1.15.0/libexec/lib/python3.13/site-packages/litecli/sqlcompleter.py", line 369, in extend_functions
    func_data = [self.escaped_names(d) for d in func_data]
                                                ^^^^^^^^^
  File "/opt/homebrew/Cellar/litecli/1.15.0/libexec/lib/python3.13/site-packages/litecli/sqlexecute.py", line 188, in functions
    cur.execute(self.functions_query % self.dbname)
    ~~~~~~~~~~~^^^^^^^^^^^^^^^^^^^^^^^^^^^^^^^^^^^^
sqlite3.OperationalError: no such table: INFORMATION_SCHEMA.ROUTINES
